Workbook

Sheet Summary Dashboard
A2: July's Quality Construction
A3: Master Project Estimate & Profit Analysis Template
A5: Job Name: | D5: Date:
A6: Customer Name:
A7: Customer Address:
A8: Customer Phone:
A10: Category | B10: Internal Cost (Us) | C10: Retail Price (Customer) | D10: Profit Difference | E10: Margin %
A11: Materials & Fees Total (Incl. Tax) | B11: ='Materials Estimate'!D31 | C11: ='Materials Estimate'!F31 | D11: =C11-B11 | E11: =IF(C11>0, D11/C11, 0)
A12: Labor Total (Standard Baseline) | B12: ='Labor Estimate'!D51 | C12: ='Labor Estimate'!F51 | D12: =C12-B12 | E12: =IF(C12>0, D12/C12, 0)
A13: Subcontractor Total | B13: =Subs!D25 | C13: =Subs!F25 | D13: =C13-B13 | E13: =IF(C13>0, D13/C13, 0)
A14: SUBTOTALS | B14: =B11+B12+B13 | C14: =C11+C12+C13 | D14: =C14-B14 | E14: =IF(C14>0, D14/C14, 0)
A15: Sales Commission (6%) | B15: 0 | C15: =C14*0.06 | D15: =C15-B15 | E15: 0.0%
A16: GRAND TOTALS | B16: =B14+B15 | C16: =C14+C15 | D16: =C16-B16 | E16: =IF(C16>0, D16/C16, 0)
A18: PAYMENT SCHEDULE
A19: Total Contract Amount | C19: =C16
A20: Due at Signing (1/2 Down) | B20: 50% | C20: =C19*0.5
A21: Due at Start of Job (1/4) | B21: 25% | C21: =C19*0.25
A22: Due Upon Completion (1/4) | B22: 25% | C22: =C19*0.25
A23: Payment Total (Verify) | C23: =C20+C21+C22

Sheet Materials Estimate
A2: Materials Cost Breakdown & Markup Template | E2: Tax Rate: | F2: 0.06
A3: Material Item | B3: Qty | C3: Unit Cost | D3: Our Cost (+6% Tax) | E3: Markup % / Fixed | F3: Customer Price
D5: =IF(COUNTA(B5:C5)=2, (B5*C5)*(1+$F$2), 0) | E5: 0.25 | F5: =IF(D5>0, D5*(1+E5), 0)
D6: =IF(COUNTA(B6:C6)=2, (B6*C6)*(1+$F$2), 0) | E6: 0.25 | F6: =IF(D6>0, D6*(1+E6), 0)
D7: =IF(COUNTA(B7:C7)=2, (B7*C7)*(1+$F$2), 0) | E7: 0.25 | F7: =IF(D7>0, D7*(1+E7), 0)
D8: =IF(COUNTA(B8:C8)=2, (B8*C8)*(1+$F$2), 0) | E8: 0.25 | F8: =IF(D8>0, D8*(1+E8), 0)
D9: =IF(COUNTA(B9:C9)=2, (B9*C9)*(1+$F$2), 0) | E9: 0.25 | F9: =IF(D9>0, D9*(1+E9), 0)
D10: =IF(COUNTA(B10:C10)=2, (B10*C10)*(1+$F$2), 0) | E10: 0.25 | F10: =IF(D10>0, D10*(1+E10), 0)
D11: =IF(COUNTA(B11:C11)=2, (B11*C11)*(1+$F$2), 0) | E11: 0.25 | F11: =IF(D11>0, D11*(1+E11), 0)
D12: =IF(COUNTA(B12:C12)=2, (B12*C12)*(1+$F$2), 0) | E12: 0.25 | F12: =IF(D12>0, D12*(1+E12), 0)
D13: =IF(COUNTA(B13:C13)=2, (B13*C13)*(1+$F$2), 0) | E13: 0.25 | F13: =IF(D13>0, D13*(1+E13), 0)
D14: =IF(COUNTA(B14:C14)=2, (B14*C14)*(1+$F$2), 0) | E14: 0.25 | F14: =IF(D14>0, D14*(1+E14), 0)
D15: =IF(COUNTA(B15:C15)=2, (B15*C15)*(1+$F$2), 0) | E15: 0.25 | F15: =IF(D15>0, D15*(1+E15), 0)
D16: =IF(COUNTA(B16:C16)=2, (B16*C16)*(1+$F$2), 0) | E16: 0.25 | F16: =IF(D16>0, D16*(1+E16), 0)
... D29: =IF(COUNTA(B29:C29)=2, (B29*C29)*(1+$F$2), 0) | E29: 0.25 | F29: =IF(D29>0, D29*(1+E29), 0)
A30: Dump Fee | D30: =IF(B30>0, B30*300, 0) | E30: Fixed Markup | F30: =IF(B30>0, B30*500, 0)
A31: Total Materials & Fees | D31: =SUM(D5:D30)+SUM(D36:D45) | F31: =SUM(F5:F30)+SUM(F36:F45)
A34: SHOWROOM MATERIALS (DIRECT VS RETAIL)
A35: Showroom Item Description | B35: Qty | C35: Direct Cost/Unit | D35: Total Internal Cost (+6% Tax) | E35: Showroom Retail Price/Unit | F35: Customer Price | G35: Profit ($)
D36: =IF(B36>0, B36*C36*1.06, 0) | F36: =IF(B36>0, B36*E36, 0) | G36: =F36-D36
D37: =IF(B37>0, B37*C37*1.06, 0) | F37: =IF(B37>0, B37*E37, 0) | G37: =F37-D37
D38: =IF(B38>0, B38*C38*1.06, 0) | F38: =IF(B38>0, B38*E38, 0) | G38: =F38-D38
D39: =IF(B39>0, B39*C39*1.06, 0) | F39: =IF(B39>0, B39*E39, 0) | G39: =F39-D39
D40: =IF(B40>0, B40*C40*1.06, 0) | F40: =IF(B40>0, B40*E40, 0) | G40: =F40-D40
D41: =IF(B41>0, B41*C41*1.06, 0) | F41: =IF(B41>0, B41*E41, 0) | G41: =F41-D41
D42: =IF(B42>0, B42*C42*1.06, 0) | F42: =IF(B42>0, B42*E42, 0) | G42: =F42-D42
D43: =IF(B43>0, B43*C43*1.06, 0) | F43: =IF(B43>0, B43*E43, 0) | G43: =F43-D43
D44: =IF(B44>0, B44*C44*1.06, 0) | F44: =IF(B44>0, B44*E44, 0) | G44: =F44-D44
D45: =IF(B45>0, B45*C45*1.06, 0) | F45: =IF(B45>0, B45*E45, 0) | G45: =F45-D45
A46: Total Showroom Profit | D46: =SUM(D36:D45) | F46: =SUM(F36:F45) | G46: =SUM(G36:G45)

Sheet Labor Estimate
A2: Labor Rate & Time Estimator Template | E2: Standard Cost/Hr: | F2: 35
E3: Standard Retail/Hr: | F3: 75
A4: Labor Task Description | B4: Hours / Qty | C4: Our Rate | D4: Our Total Cost | E4: Retail Rate | F4: Customer Total Price
A5: #Demolition | C5: =$F$2 | D5: =IF(B5>0, B5*C5, 0) | E5: =$F$3 | F5: =IF(B5>0, B5*E5, 0)
C6: =$F$2 | D6: =IF(B6>0, B6*C6, 0) | E6: =$F$3 | F6: =IF(B6>0, B6*E6, 0)
C7: =$F$2 | D7: =IF(B7>0, B7*C7, 0) | E7: =$F$3 | F7: =IF(B7>0, B7*E7, 0)
C8: =$F$2 | D8: =IF(B8>0, B8*C8, 0) | E8: =$F$3 | F8: =IF(B8>0, B8*E8, 0)
C9: =$F$2 | D9: =IF(B9>0, B9*C9, 0) | E9: =$F$3 | F9: =IF(B9>0, B9*E9, 0)
A10: #Carpentry | C10: =$F$2 | D10: =IF(B10>0, B10*C10, 0) | E10: =$F$3 | F10: =IF(B10>0, B10*E10, 0)
C11: =$F$2 | D11: =IF(B11>0, B11*C11, 0) | E11: =$F$3 | F11: =IF(B11>0, B11*E11, 0)
C12: =$F$2 | D12: =IF(B12>0, B12*C12, 0) | E12: =$F$3 | F12: =IF(B12>0, B12*E12, 0)
C13: =$F$2 | D13: =IF(B13>0, B13*C13, 0) | E13: =$F$3 | F13: =IF(B13>0, B13*E13, 0)
C14: =$F$2 | D14: =IF(B14>0, B14*C14, 0) | E14: =$F$3 | F14: =IF(B14>0, B14*E14, 0)
C15: =$F$2 | D15: =IF(B15>0, B15*C15, 0) | E15: =$F$3 | F15: =IF(B15>0, B15*E15, 0)
C16: =$F$2 | D16: =IF(B16>0, B16*C16, 0) | E16: =$F$3 | F16: =IF(B16>0, B16*E16, 0)
C17: =$F$2 | D17: =IF(B17>0, B17*C17, 0) | E17: =$F$3 | F17: =IF(B17>0, B17*E17, 0)
C18: =$F$2 | D18: =IF(B18>0, B18*C18, 0) | E18: =$F$3 | F18: =IF(B18>0, B18*E18, 0)
C19: =$F$2 | D19: =IF(B19>0, B19*C19, 0) | E19: =$F$3 | F19: =IF(B19>0, B19*E19, 0)
C20: =$F$2 | D20: =IF(B20>0, B20*C20, 0) | E20: =$F$3 | F20: =IF(B20>0, B20*E20, 0)
C21: =$F$2 | D21: =IF(B21>0, B21*C21, 0) | E21: =$F$3 | F21: =IF(B21>0, B21*E21, 0)
C22: =$F$2 | D22: =IF(B22>0, B22*C22, 0) | E22: =$F$3 | F22: =IF(B22>0, B22*E22, 0)
... C25: =$F$2 | D25: =IF(B25>0, B25*C25, 0) | E25: =$F$3 | F25: =IF(B25>0, B25*E25, 0)
A26: #Plumbing | C26: =$F$2 | D26: =IF(B26>0, B26*C26, 0) | E26: =$F$3 | F26: =IF(B26>0, B26*E26, 0)
C27: =$F$2 | D27: =IF(B27>0, B27*C27, 0) | E27: =$F$3 | F27: =IF(B27>0, B27*E27, 0)
C28: =$F$2 | D28: =IF(B28>0, B28*C28, 0) | E28: =$F$3 | F28: =IF(B28>0, B28*E28, 0)
C29: =$F$2 | D29: =IF(B29>0, B29*C29, 0) | E29: =$F$3 | F29: =IF(B29>0, B29*E29, 0)
C30: =$F$2 | D30: =IF(B30>0, B30*C30, 0) | E30: =$F$3 | F30: =IF(B30>0, B30*E30, 0)
C31: =$F$2 | D31: =IF(B31>0, B31*C31, 0) | E31: =$F$3 | F31: =IF(B31>0, B31*E31, 0)
C32: =$F$2 | D32: =IF(B32>0, B32*C32, 0) | E32: =$F$3 | F32: =IF(B32>0, B32*E32, 0)
C33: =$F$2 | D33: =IF(B33>0, B33*C33, 0) | E33: =$F$3 | F33: =IF(B33>0, B33*E33, 0)
C34: =$F$2 | D34: =IF(B34>0, B34*C34, 0) | E34: =$F$3 | F34: =IF(B34>0, B34*E34, 0)
A35: #Electrical | C35: =$F$2 | D35: =IF(B35>0, B35*C35, 0) | E35: =$F$3 | F35: =IF(B35>0, B35*E35, 0)
C36: =$F$2 | D36: =IF(B36>0, B36*C36, 0) | E36: =$F$3 | F36: =IF(B36>0, B36*E36, 0)
C37: =$F$2 | D37: =IF(B37>0, B37*C37, 0) | E37: =$F$3 | F37: =IF(B37>0, B37*E37, 0)
C38: =$F$2 | D38: =IF(B38>0, B38*C38, 0) | E38: =$F$3 | F38: =IF(B38>0, B38*E38, 0)
C39: =$F$2 | D39: =IF(B39>0, B39*C39, 0) | E39: =$F$3 | F39: =IF(B39>0, B39*E39, 0)
C40: =$F$2 | D40: =IF(B40>0, B40*C40, 0) | E40: =$F$3 | F40: =IF(B40>0, B40*E40, 0)
C41: =$F$2 | D41: =IF(B41>0, B41*C41, 0) | E41: =$F$3 | F41: =IF(B41>0, B41*E41, 0)
C42: =$F$2 | D42: =IF(B42>0, B42*C42, 0) | E42: =$F$3 | F42: =IF(B42>0, B42*E42, 0)
C43: =$F$2 | D43: =IF(B43>0, B43*C43, 0) | E43: =$F$3 | F43: =IF(B43>0, B43*E43, 0)
...

Sheet Subs
A1: Subcontractor/Trade | B1: Qty | C1: Our Direct Cost/Unit | D1: Total Internal Cost | E1: Markup% | F1: Customer Retail Price | G1: Profit ($)
A2: #Plumbing | D2: =IF(B2>0, B2*C2, 0) | E2: 0.4286 | F2: =IF(D2>0, D2*(1+E2), 0) | G2: =F2-D2
D3: =IF(B3>0, B3*C3, 0) | E3: 0.4286 | F3: =IF(D3>0, D3*(1+E3), 0) | G3: =F3-D3
D4: =IF(B4>0, B4*C4, 0) | E4: 0.4286 | F4: =IF(D4>0, D4*(1+E4), 0) | G4: =F4-D4
D5: =IF(B5>0, B5*C5, 0) | E5: 0.4286 | F5: =IF(D5>0, D5*(1+E5), 0) | G5: =F5-D5
A6: #Electrical | D6: =IF(B6>0, B6*C6, 0) | E6: 0.4286 | F6: =IF(D6>0, D6*(1+E6), 0) | G6: =F6-D6
D7: =IF(B7>0, B7*C7, 0) | E7: 0.4286 | F7: =IF(D7>0, D7*(1+E7), 0) | G7: =F7-D7
D8: =IF(B8>0, B8*C8, 0) | E8: 0.4286 | F8: =IF(D8>0, D8*(1+E8), 0) | G8: =F8-D8
D9: =IF(B9>0, B9*C9, 0) | E9: 0.4286 | F9: =IF(D9>0, D9*(1+E9), 0) | G9: =F9-D9
A10: #Drywall | D10: =IF(B10>0, B10*C10, 0) | E10: 0.4286 | F10: =IF(D10>0, D10*(1+E10), 0) | G10: =F10-D10
D11: =IF(B11>0, B11*C11, 0) | E11: 0.4286 | F11: =IF(D11>0, D11*(1+E11), 0) | G11: =F11-D11
D12: =IF(B12>0, B12*C12, 0) | E12: 0.4286 | F12: =IF(D12>0, D12*(1+E12), 0) | G12: =F12-D12
D13: =IF(B13>0, B13*C13, 0) | E13: 0.4286 | F13: =IF(D13>0, D13*(1+E13), 0) | G13: =F13-D13
A14: #Masonry | D14: =IF(B14>0, B14*C14, 0) | E14: 0.4286 | F14: =IF(D14>0, D14*(1+E14), 0) | G14: =F14-D14
D15: =IF(B15>0, B15*C15, 0) | E15: 0.4286 | F15: =IF(D15>0, D15*(1+E15), 0) | G15: =F15-D15
D16: =IF(B16>0, B16*C16, 0) | E16: 0.4286 | F16: =IF(D16>0, D16*(1+E16), 0) | G16: =F16-D16
D17: =IF(B17>0, B17*C17, 0) | E17: 0.4286 | F17: =IF(D17>0, D17*(1+E17), 0) | G17: =F17-D17
A18: #Painting | D18: =IF(B18>0, B18*C18, 0) | E18: 0.4286 | F18: =IF(D18>0, D18*(1+E18), 0) | G18: =F18-D18
D19: =IF(B19>0, B19*C19, 0) | E19: 0.4286 | F19: =IF(D19>0, D19*(1+E19), 0) | G19: =F19-D19
D20: =IF(B20>0, B20*C20, 0) | E20: 0.4286 | F20: =IF(D20>0, D20*(1+E20), 0) | G20: =F20-D20
D21: =IF(B21>0, B21*C21, 0) | E21: 0.4286 | F21: =IF(D21>0, D21*(1+E21), 0) | G21: =F21-D21
D22: =IF(B22>0, B22*C22, 0) | E22: 0.4286 | F22: =IF(D22>0, D22*(1+E22), 0) | G22: =F22-D22
D23: =IF(B23>0, B23*C23, 0) | E23: 0.4286 | F23: =IF(D23>0, D23*(1+E23), 0) | G23: =F23-D23
A25: Total Sub Cost | D25: =SUM(D2:D23) | F25: =SUM(F2:F23) | G25: =SUM(G2:G23)
